Workbook

Sheet Grating
A1: Slit form and type | B1: Period, μm | C1: Duty factor | D1: Slit depth, mm | E1: Refractive index
A2: 1D,square | B2: 100 | C2: 0.3 | D2: =0.5*0.0007 -> 0.00035 | E2: 1.4738 | F2: -25.593
A3: =+A2 -> 1D,square | B3: =+B2 -> 100 | C3: =+C2 -> 0.3 | D3: =+D2 -> 0.00035 | E3: =+E2 -> 1.4738 | F3: -25.593
A4: =+A3 -> 1D,square | B4: =+B3 -> 100 | C4: =+C3 -> 0.3 | D4: =+D3 -> 0.00035 | E4: =+E3 -> 1.4738 | F4: -25.593
A5: =+A4 -> 1D,square | B5: =+B4 -> 100 | C5: =+C4 -> 0.3 | D5: =+D4 -> 0.00035 | E5: =+E4 -> 1.4738 | F5: -25.593
A6: =+A5 -> 1D,square | B6: =+B5 -> 100 | C6: =+C5 -> 0.3 | D6: =+D5 -> 0.00035 | E6: =+E5 -> 1.4738 | F6: -25.593
A7: =+A6 -> 1D,square | B7: =+B6 -> 100 | C7: =+C6 -> 0.3 | D7: =+D6 -> 0.00035 | E7: =+E6 -> 1.4738 | F7: -25.593
A8: =+A7 -> 1D,square | B8: =+B7 -> 100 | C8: =+C7 -> 0.3 | D8: =+D7 -> 0.00035 | E8: =+E7 -> 1.4738 | F8: -25.593
A9: =+A8 -> 1D,square | B9: =+B8 -> 100 | C9: =+C8 -> 0.3 | D9: =+D8 -> 0.00035 | E9: =+E8 -> 1.4738 | F9: -25.593
A10: =+A9 -> 1D,square | B10: =+B9 -> 100 | C10: =+C9 -> 0.3 | D10: =+D9 -> 0.00035 | E10: =+E9 -> 1.4738 | F10: -25.593
A11: =+A10 -> 1D,square | B11: =+B10 -> 100 | C11: =+C10 -> 0.3 | D11: =+D10 -> 0.00035 | E11: =+E10 -> 1.4738 | F11: -25.593
A12: =+A11 -> 1D,square | B12: =+B11 -> 100 | C12: =+C11 -> 0.3 | D12: =+D11 -> 0.00035 | E12: =+E11 -> 1.4738 | F12: -25.593
A13: =+A12 -> 1D,square | B13: =+B12 -> 100 | C13: =+C12 -> 0.3 | D13: =+D12 -> 0.00035 | E13: =+E12 -> 1.4738 | F13: -25.593
A14: =+A13 -> 1D,square | B14: =+B13 -> 100 | C14: =+C13 -> 0.3 | D14: =+D13 -> 0.00035 | E14: =+E13 -> 1.4738 | F14: -25.593
... A402: =+A401 -> 1D,square | B402: =+B401 -> 100 | C402: =+C401 -> 0.3 | D402: =+D401 -> 0.00035 | E402: =+E401 -> 1.4738 | F402: 176.407

Sheet Beam
A1: Wavelength, nm | B1: Band width, % | C1: Intensity, W/mm²
A2: 500 | B2: 0 | C2: 1
A3: =+A2 -> 500 | B3: =+B2 -> 0 | C3: =+C2 -> 1
A4: =+A3 -> 500 | B4: =+B3 -> 0 | C4: =+C3 -> 1
A5: =+A4 -> 500 | B5: =+B4 -> 0 | C5: =+C4 -> 1
A6: =+A5 -> 500 | B6: =+B5 -> 0 | C6: =+C5 -> 1
A7: =+A6 -> 500 | B7: =+B6 -> 0 | C7: =+C6 -> 1
A8: =+A7 -> 500 | B8: =+B7 -> 0 | C8: =+C7 -> 1
A9: =+A8 -> 500 | B9: =+B8 -> 0 | C9: =+C8 -> 1
A10: =+A9 -> 500 | B10: =+B9 -> 0 | C10: =+C9 -> 1
A11: =+A10 -> 500 | B11: =+B10 -> 0 | C11: =+C10 -> 1
A12: =+A11 -> 500 | B12: =+B11 -> 0 | C12: =+C11 -> 1
A13: =+A12 -> 500 | B13: =+B12 -> 0 | C13: =+C12 -> 1
A14: =+A13 -> 500 | B14: =+B13 -> 0 | C14: =+C13 -> 1
... A402: =+A401 -> 500 | B402: =+B401 -> 0 | C402: =+C401 -> 1

Sheet Beam.X
A1: Gaussian waist, mm⁻¹ | B1: Beam aperture, mm⁻¹ | C1: Incidence angle, mrad | D1: Wavefront curvature, mm⁻¹ | E1: Aberration function
A2: 0 | B2: 0 | C2: 0 | D2: 0
A3: =+A2+3/375 -> 0.008 | B3: =+B2 -> 0 | C3: =+C2 -> 0 | D3: =+D2 -> 0
A4: =+A3+3/375 -> 0.016 | B4: =+B3 -> 0 | C4: =+C3 -> 0 | D4: =+D3 -> 0
A5: =+A4+3/375 -> 0.024 | B5: =+B4 -> 0 | C5: =+C4 -> 0 | D5: =+D4 -> 0
A6: =+A5+3/375 -> 0.032 | B6: =+B5 -> 0 | C6: =+C5 -> 0 | D6: =+D5 -> 0
A7: =+A6+3/375 -> 0.04 | B7: =+B6 -> 0 | C7: =+C6 -> 0 | D7: =+D6 -> 0
A8: =+A7+3/375 -> 0.048 | B8: =+B7 -> 0 | C8: =+C7 -> 0 | D8: =+D7 -> 0
A9: =+A8+3/375 -> 0.056 | B9: =+B8 -> 0 | C9: =+C8 -> 0 | D9: =+D8 -> 0
A10: =+A9+3/375 -> 0.064 | B10: =+B9 -> 0 | C10: =+C9 -> 0 | D10: =+D9 -> 0
A11: =+A10+3/375 -> 0.072 | B11: =+B10 -> 0 | C11: =+C10 -> 0 | D11: =+D10 -> 0
A12: =+A11+3/375 -> 0.08 | B12: =+B11 -> 0 | C12: =+C11 -> 0 | D12: =+D11 -> 0
A13: =+A12+3/375 -> 0.088 | B13: =+B12 -> 0 | C13: =+C12 -> 0 | D13: =+D12 -> 0
A14: =+A13+3/375 -> 0.096 | B14: =+B13 -> 0 | C14: =+C13 -> 0 | D14: =+D13 -> 0
... A377: =+A376+3/375 -> 3 | B377: =+B376 -> 0 | C377: =+C376 -> 0 | D377: =+D376 -> 0
A378: =A377+2/25 -> 3.08 | B378: =+B377 -> 0 | C378: =+C377 -> 0 | D378: =+D377 -> 0
A379: =A378+2/25 -> 3.16 | B379: =+B378 -> 0 | C379: =+C378 -> 0 | D379: =+D378 -> 0
A380: =A379+2/25 -> 3.24 | B380: =+B379 -> 0 | C380: =+C379 -> 0 | D380: =+D379 -> 0
A381: =A380+2/25 -> 3.32 | B381: =+B380 -> 0 | C381: =+C380 -> 0 | D381: =+D380 -> 0
A382: =A381+2/25 -> 3.4 | B382: =+B381 -> 0 | C382: =+C381 -> 0 | D382: =+D381 -> 0
A383: =A382+2/25 -> 3.48 | B383: =+B382 -> 0 | C383: =+C382 -> 0 | D383: =+D382 -> 0
A384: =A383+2/25 -> 3.56 | B384: =+B383 -> 0 | C384: =+C383 -> 0 | D384: =+D383 -> 0
A385: =A384+2/25 -> 3.64 | B385: =+B384 -> 0 | C385: =+C384 -> 0 | D385: =+D384 -> 0
A386: =A385+2/25 -> 3.72 | B386: =+B385 -> 0 | C386: =+C385 -> 0 | D386: =+D385 -> 0
A387: =A386+2/25 -> 3.8 | B387: =+B386 -> 0 | C387: =+C386 -> 0 | D387: =+D386 -> 0
A388: =A387+2/25 -> 3.88 | B388: =+B387 -> 0 | C388: =+C387 -> 0 | D388: =+D387 -> 0
A389: =A388+2/25 -> 3.96 | B389: =+B388 -> 0 | C389: =+C388 -> 0 | D389: =+D388 -> 0
... A402: =A401+2/25 -> 5 | B402: =+B401 -> 0 | C402: =+C401 -> 0 | D402: =+D401 -> 0

Sheet Beam.Y
A1: Gaussian waist, mm⁻¹ | B1: Beam aperture, mm⁻¹ | C1: Incidence angle, mrad | D1: Wavefront curvature, mm⁻¹ | E1: Aberration function
A2: 0 | B2: 0 | C2: 0 | D2: 0
A3: =+A2 -> 0 | B3: =+B2 -> 0 | C3: =+C2 -> 0 | D3: =+D2 -> 0
A4: =+A3 -> 0 | B4: =+B3 -> 0 | C4: =+C3 -> 0 | D4: =+D3 -> 0
A5: =+A4 -> 0 | B5: =+B4 -> 0 | C5: =+C4 -> 0 | D5: =+D4 -> 0
A6: =+A5 -> 0 | B6: =+B5 -> 0 | C6: =+C5 -> 0 | D6: =+D5 -> 0
A7: =+A6 -> 0 | B7: =+B6 -> 0 | C7: =+C6 -> 0 | D7: =+D6 -> 0
A8: =+A7 -> 0 | B8: =+B7 -> 0 | C8: =+C7 -> 0 | D8: =+D7 -> 0
A9: =+A8 -> 0 | B9: =+B8 -> 0 | C9: =+C8 -> 0 | D9: =+D8 -> 0
A10: =+A9 -> 0 | B10: =+B9 -> 0 | C10: =+C9 -> 0 | D10: =+D9 -> 0
A11: =+A10 -> 0 | B11: =+B10 -> 0 | C11: =+C10 -> 0 | D11: =+D10 -> 0
A12: =+A11 -> 0 | B12: =+B11 -> 0 | C12: =+C11 -> 0 | D12: =+D11 -> 0
A13: =+A12 -> 0 | B13: =+B12 -> 0 | C13: =+C12 -> 0 | D13: =+D12 -> 0
A14: =+A13 -> 0 | B14: =+B13 -> 0 | C14: =+C13 -> 0 | D14: =+D13 -> 0
... A402: =+A401 -> 0 | B402: =+B401 -> 0 | C402: =+C401 -> 0 | D402: =+D401 -> 0

Sheet Psd
A1: Distance, mm | B1: Image aperture, mm | C1: Lateral step, μm | D1: Step division
A2: =2*Grating!B2*Grating!B2/Beam!A2 -> 40 | B2: 2 | C2: 5 | D2: 40
A3: =2*Grating!B3*Grating!B3/Beam!A3 -> 40 | B3: =+B2 -> 2 | C3: =+C2 -> 5 | D3: =+D2 -> 40
A4: =2*Grating!B4*Grating!B4/Beam!A4 -> 40 | B4: =+B3 -> 2 | C4: =+C3 -> 5 | D4: =+D3 -> 40
A5: =2*Grating!B5*Grating!B5/Beam!A5 -> 40 | B5: =+B4 -> 2 | C5: =+C4 -> 5 | D5: =+D4 -> 40
A6: =2*Grating!B6*Grating!B6/Beam!A6 -> 40 | B6: =+B5 -> 2 | C6: =+C5 -> 5 | D6: =+D5 -> 40
A7: =2*Grating!B7*Grating!B7/Beam!A7 -> 40 | B7: =+B6 -> 2 | C7: =+C6 -> 5 | D7: =+D6 -> 40
A8: =2*Grating!B8*Grating!B8/Beam!A8 -> 40 | B8: =+B7 -> 2 | C8: =+C7 -> 5 | D8: =+D7 -> 40
A9: =2*Grating!B9*Grating!B9/Beam!A9 -> 40 | B9: =+B8 -> 2 | C9: =+C8 -> 5 | D9: =+D8 -> 40
A10: =2*Grating!B10*Grating!B10/Beam!A10 -> 40 | B10: =+B9 -> 2 | C10: =+C9 -> 5 | D10: =+D9 -> 40
A11: =2*Grating!B11*Grating!B11/Beam!A11 -> 40 | B11: =+B10 -> 2 | C11: =+C10 -> 5 | D11: =+D10 -> 40
A12: =2*Grating!B12*Grating!B12/Beam!A12 -> 40 | B12: =+B11 -> 2 | C12: =+C11 -> 5 | D12: =+D11 -> 40
A13: =2*Grating!B13*Grating!B13/Beam!A13 -> 40 | B13: =+B12 -> 2 | C13: =+C12 -> 5 | D13: =+D12 -> 40
A14: =2*Grating!B14*Grating!B14/Beam!A14 -> 40 | B14: =+B13 -> 2 | C14: =+C13 -> 5 | D14: =+D13 -> 40
... A402: =2*Grating!B402*Grating!B402/Beam!A402 -> 40 | B402: =+B401 -> 2 | C402: =+C401 -> 5 | D402: =+D401 -> 40

Sheet Add
A1: Accuracy, % | B1: Debug data | C1: Save data
A2: 1 | B2: N | C2: N
A3: =+A2 -> 1 | B3: N | C3: N
A4: =+A3 -> 1 | B4: N | C4: N
A5: =+A4 -> 1 | B5: N | C5: N
A6: =+A5 -> 1 | B6: N | C6: N
A7: =+A6 -> 1 | B7: N | C7: N
A8: =+A7 -> 1 | B8: N | C8: N
A9: =+A8 -> 1 | B9: N | C9: N
A10: =+A9 -> 1 | B10: N | C10: N
A11: =+A10 -> 1 | B11: N | C11: N
A12: =+A11 -> 1 | B12: N | C12: N
A13: =+A12 -> 1 | B13: N | C13: N
A14: =+A13 -> 1 | B14: N | C14: N
... A26: =+A25 -> 1 | B26: N | C26: N
A27: =+A26 -> 1 | B27: N | C27: =+C19 -> N
A28: =+A27 -> 1 | B28: N | C28: =+C20 -> N
A29: =+A28 -> 1 | B29: N | C29: =+C21 -> N
A30: =+A29 -> 1 | B30: N | C30: =+C22 -> N
A31: =+A30 -> 1 | B31: N | C31: =+C23 -> N
A32: =+A31 -> 1 | B32: N | C32: =+C24 -> N
A33: =+A32 -> 1 | B33: N | C33: =+C25 -> N
A34: =+A33 -> 1 | B34: N | C34: =+C26 -> N
A35: =+A34 -> 1 | B35: N | C35: =+C27 -> N
A36: =+A35 -> 1 | B36: N | C36: =+C28 -> N
A37: =+A36 -> 1 | B37: N | C37: =+C29 -> N
A38: =+A37 -> 1 | B38: N | C38: =+C30 -> N
... A99: =+A98 -> 1 | B99: N | C99: =+C91 -> N
A100: =+A99 -> 1 | B100: N | C100: =+C2 -> N
A101: =+A100 -> 1 | B101: N | C101: =+C3 -> N
A102: =+A101 -> 1 | B102: N | C102: =+C4 -> N
A103: =+A102 -> 1 | B103: N | C103: =+C5 -> N
A104: =+A103 -> 1 | B104: N | C104: =+C6 -> N
A105: =+A104 -> 1 | B105: N | C105: =+C7 -> N
A106: =+A105 -> 1 | B106: N | C106: =+C8 -> N
A107: =+A106 -> 1 | B107: N | C107: =+C9 -> N
A108: =+A107 -> 1 | B108: N | C108: =+C10 -> N
A109: =+A108 -> 1 | B109: N | C109: =+C11 -> N
A110: =+A109 -> 1 | B110: N | C110: =+C12 -> N
A111: =+A110 -> 1 | B111: N | C111: =+C13 -> N
...

Sheet Dependencies
A1: List of dependencies
A2: x waist
