Workbook

Sheet Grating
A1: Slit form and type | B1: Period, μm | C1: Duty factor | D1: Slit depth, mm | E1: Refractive index
A2: 2D,square, | B2: 100 | C2: 0.5 | D2: =0.5*0.0007 -> 0.00035 | E2: 1.4738 | F2: -25.593
A3: =+A2 -> 2D,square, | B3: =+B2 -> 100 | C3: =+C2 -> 0.5 | D3: =+D2 -> 0.00035 | E3: =+E2 -> 1.4738 | F3: -25.593
A4: =+A3 -> 2D,square, | B4: =+B3 -> 100 | C4: =+C3 -> 0.5 | D4: =+D3 -> 0.00035 | E4: =+E3 -> 1.4738 | F4: -25.593
A5: =+A4 -> 2D,square, | B5: =+B4 -> 100 | C5: =+C4 -> 0.5 | D5: =+D4 -> 0.00035 | E5: =+E4 -> 1.4738 | F5: -25.593
A6: =+A5 -> 2D,square, | B6: =+B5 -> 100 | C6: =+C5 -> 0.5 | D6: =+D5 -> 0.00035 | E6: =+E5 -> 1.4738 | F6: -25.593
A7: =+A6 -> 2D,square, | B7: =+B6 -> 100 | C7: =+C6 -> 0.5 | D7: =+D6 -> 0.00035 | E7: =+E6 -> 1.4738 | F7: -25.593
A8: =+A7 -> 2D,square, | B8: =+B7 -> 100 | C8: =+C7 -> 0.5 | D8: =+D7 -> 0.00035 | E8: =+E7 -> 1.4738 | F8: -25.593
A9: =+A8 -> 2D,square, | B9: =+B8 -> 100 | C9: =+C8 -> 0.5 | D9: =+D8 -> 0.00035 | E9: =+E8 -> 1.4738 | F9: -25.593
A10: =+A9 -> 2D,square, | B10: =+B9 -> 100 | C10: =+C9 -> 0.5 | D10: =+D9 -> 0.00035 | E10: =+E9 -> 1.4738 | F10: -25.593
A11: =+A10 -> 2D,square, | B11: =+B10 -> 100 | C11: =+C10 -> 0.5 | D11: =+D10 -> 0.00035 | E11: =+E10 -> 1.4738 | F11: -25.593
A12: =+A11 -> 2D,square, | B12: =+B11 -> 100 | C12: =+C11 -> 0.5 | D12: =+D11 -> 0.00035 | E12: =+E11 -> 1.4738 | F12: -25.593
A13: =+A12 -> 2D,square, | B13: =+B12 -> 100 | C13: =+C12 -> 0.5 | D13: =+D12 -> 0.00035 | E13: =+E12 -> 1.4738 | F13: -25.593
A14: =+A13 -> 2D,square, | B14: =+B13 -> 100 | C14: =+C13 -> 0.5 | D14: =+D13 -> 0.00035 | E14: =+E13 -> 1.4738 | F14: -25.593
... A211: =+A210 -> 2D,square, | B211: =+B210 -> 100 | C211: =+C210 -> 0.5 | D211: =+D210 -> 0.00035 | E211: =+E210 -> 1.4738 | F211: -14.593

Sheet Beam
A1: Wavelength, nm | B1: Band width, % | C1: Intensity, W/mm² | D1: Pulse width, ps | E1: Pulse chirp | F1: Refractive index
A2: 500 | B2: 0 | C2: 1 | E2: 0 | F2: 1.4738 | G2: -25.593
A3: =+A2 -> 500 | B3: =+B2 -> 0 | C3: =+C2 -> 1 | E3: 0 | F3: =+F2 -> 1.4738 | G3: =+G2 -> -25.593
A4: =+A3 -> 500 | B4: =+B3 -> 0 | C4: =+C3 -> 1 | E4: 0 | F4: =+F3 -> 1.4738 | G4: =+G3 -> -25.593
A5: =+A4 -> 500 | B5: =+B4 -> 0 | C5: =+C4 -> 1 | E5: 0 | F5: =+F4 -> 1.4738 | G5: =+G4 -> -25.593
A6: =+A5 -> 500 | B6: =+B5 -> 0 | C6: =+C5 -> 1 | E6: 0 | F6: =+F5 -> 1.4738 | G6: =+G5 -> -25.593
A7: =+A6 -> 500 | B7: =+B6 -> 0 | C7: =+C6 -> 1 | E7: 0 | F7: =+F6 -> 1.4738 | G7: =+G6 -> -25.593
A8: =+A7 -> 500 | B8: =+B7 -> 0 | C8: =+C7 -> 1 | E8: 0 | F8: =+F7 -> 1.4738 | G8: =+G7 -> -25.593
A9: =+A8 -> 500 | B9: =+B8 -> 0 | C9: =+C8 -> 1 | E9: 0 | F9: =+F8 -> 1.4738 | G9: =+G8 -> -25.593
A10: =+A9 -> 500 | B10: =+B9 -> 0 | C10: =+C9 -> 1 | E10: 0 | F10: =+F9 -> 1.4738 | G10: =+G9 -> -25.593
A11: =+A10 -> 500 | B11: =+B10 -> 0 | C11: =+C10 -> 1 | E11: 0 | F11: =+F10 -> 1.4738 | G11: =+G10 -> -25.593
A12: =+A11 -> 500 | B12: =+B11 -> 0 | C12: =+C11 -> 1 | E12: 0 | F12: =+F11 -> 1.4738 | G12: =+G11 -> -25.593
A13: =+A12 -> 500 | B13: =+B12 -> 0 | C13: =+C12 -> 1 | E13: 0 | F13: =+F12 -> 1.4738 | G13: =+G12 -> -25.593
A14: =+A13 -> 500 | B14: =+B13 -> 0 | C14: =+C13 -> 1 | E14: 0 | F14: =+F13 -> 1.4738 | G14: =+G13 -> -25.593
... A22: =+A21 -> 500 | B22: =+B21 -> 0 | C22: =+C21 -> 1 | E22: 0 | F22: =+F21 -> 1.4738 | G22: =+G21 -> -25.593
A23: =+A22 -> 500 | B23: =+B2+5 -> 5 | C23: =+C22 -> 1 | E23: 0 | F23: =+F22 -> 1.4738 | G23: =+G22 -> -25.593
A24: =+A23 -> 500 | B24: =+B3+5 -> 5 | C24: =+C23 -> 1 | E24: 0 | F24: =+F23 -> 1.4738 | G24: =+G23 -> -25.593
A25: =+A24 -> 500 | B25: =+B4+5 -> 5 | C25: =+C24 -> 1 | E25: 0 | F25: =+F24 -> 1.4738 | G25: =+G24 -> -25.593
A26: =+A25 -> 500 | B26: =+B5+5 -> 5 | C26: =+C25 -> 1 | E26: 0 | F26: =+F25 -> 1.4738 | G26: =+G25 -> -25.593
A27: =+A26 -> 500 | B27: =+B6+5 -> 5 | C27: =+C26 -> 1 | E27: 0 | F27: =+F26 -> 1.4738 | G27: =+G26 -> -25.593
A28: =+A27 -> 500 | B28: =+B7+5 -> 5 | C28: =+C27 -> 1 | E28: 0 | F28: =+F27 -> 1.4738 | G28: =+G27 -> -25.593
A29: =+A28 -> 500 | B29: =+B8+5 -> 5 | C29: =+C28 -> 1 | E29: 0 | F29: =+F28 -> 1.4738 | G29: =+G28 -> -25.593
A30: =+A29 -> 500 | B30: =+B9+5 -> 5 | C30: =+C29 -> 1 | E30: 0 | F30: =+F29 -> 1.4738 | G30: =+G29 -> -25.593
A31: =+A30 -> 500 | B31: =+B10+5 -> 5 | C31: =+C30 -> 1 | E31: 0 | F31: =+F30 -> 1.4738 | G31: =+G30 -> -25.593
A32: =+A31 -> 500 | B32: =+B11+5 -> 5 | C32: =+C31 -> 1 | E32: 0 | F32: =+F31 -> 1.4738 | G32: =+G31 -> -25.593
A33: =+A32 -> 500 | B33: =+B12+5 -> 5 | C33: =+C32 -> 1 | E33: 0 | F33: =+F32 -> 1.4738 | G33: =+G32 -> -25.593
A34: =+A33 -> 500 | B34: =+B13+5 -> 5 | C34: =+C33 -> 1 | E34: 0 | F34: =+F33 -> 1.4738 | G34: =+G33 -> -25.593
... A106: =+A105 -> 500 | B106: =+B85+5 -> 20 | C106: =+C105 -> 1 | E106: 0 | F106: =+F105 -> 1.4738 | G106: =+G105 -> -25.593
A107: =+A106 -> 500 | B107: =+B2 -> 0 | C107: =+C106 -> 1 | E107: 0 | F107: =+F106 -> 1.4738 | G107: =+G106 -> -25.593
A108: =+A107 -> 500 | B108: =+B3 -> 0 | C108: =+C107 -> 1 | E108: 0 | F108: =+F107 -> 1.4738 | G108: =+G107 -> -25.593
A109: =+A108 -> 500 | B109: =+B4 -> 0 | C109: =+C108 -> 1 | E109: 0 | F109: =+F108 -> 1.4738 | G109: =+G108 -> -25.593
A110: =+A109 -> 500 | B110: =+B5 -> 0 | C110: =+C109 -> 1 | E110: 0 | F110: =+F109 -> 1.4738 | G110: =+G109 -> -25.593
A111: =+A110 -> 500 | B111: =+B6 -> 0 | C111: =+C110 -> 1 | E111: 0 | F111: =+F110 -> 1.4738 | G111: =+G110 -> -25.593
A112: =+A111 -> 500 | B112: =+B7 -> 0 | C112: =+C111 -> 1 | E112: 0 | F112: =+F111 -> 1.4738 | G112: =+G111 -> -25.593
A113: =+A112 -> 500 | B113: =+B8 -> 0 | C113: =+C112 -> 1 | E113: 0 | F113: =+F112 -> 1.4738 | G113: =+G112 -> -25.593
A114: =+A113 -> 500 | B114: =+B9 -> 0 | C114: =+C113 -> 1 | E114: 0 | F114: =+F113 -> 1.4738 | G114: =+G113 -> -25.593
A115: =+A114 -> 500 | B115: =+B10 -> 0 | C115: =+C114 -> 1 | E115: 0 | F115: =+F114 -> 1.4738 | G115: =+G114 -> -25.593
A116: =+A115 -> 500 | B116: =+B11 -> 0 | C116: =+C115 -> 1 | E116: 0 | F116: =+F115 -> 1.4738 | G116: =+G115 -> -25.593
A117: =+A116 -> 500 | B117: =+B12 -> 0 | C117: =+C116 -> 1 | E117: 0 | F117: =+F116 -> 1.4738 | G117: =+G116 -> -25.593
A118: =+A117 -> 500 | B118: =+B13 -> 0 | C118: =+C117 -> 1 | E118: 0 | F118: =+F117 -> 1.4738 | G118: =+G117 -> -25.593
...

Sheet Beam.X
A1: Gaussian waist, mm⁻¹ | B1: Beam aperture, mm⁻¹ | C1: Incidence angle, mrad | D1: Wavefront curvature, mm⁻¹ | E1: Aberration function
A2: 0 | B2: 0 | C2: 0 | D2: -0.01
A3: =+A2 -> 0 | B3: =+B2 -> 0 | C3: =+C2 -> 0 | D3: =+D2+0.001 -> -0.009
A4: =+A3 -> 0 | B4: =+B3 -> 0 | C4: =+C3 -> 0 | D4: =+D3+0.001 -> -0.008
A5: =+A4 -> 0 | B5: =+B4 -> 0 | C5: =+C4 -> 0 | D5: =+D4+0.001 -> -0.007
A6: =+A5 -> 0 | B6: =+B5 -> 0 | C6: =+C5 -> 0 | D6: =+D5+0.001 -> -0.006
A7: =+A6 -> 0 | B7: =+B6 -> 0 | C7: =+C6 -> 0 | D7: =+D6+0.001 -> -0.005
A8: =+A7 -> 0 | B8: =+B7 -> 0 | C8: =+C7 -> 0 | D8: =+D7+0.001 -> -0.004
A9: =+A8 -> 0 | B9: =+B8 -> 0 | C9: =+C8 -> 0 | D9: =+D8+0.001 -> -0.003
A10: =+A9 -> 0 | B10: =+B9 -> 0 | C10: =+C9 -> 0 | D10: =+D9+0.001 -> -0.002
A11: =+A10 -> 0 | B11: =+B10 -> 0 | C11: =+C10 -> 0 | D11: =+D10+0.001 -> -0.001
A12: =+A11 -> 0 | B12: =+B11 -> 0 | C12: =+C11 -> 0 | D12: =+D11+0.001 -> 0
A13: =+A12 -> 0 | B13: =+B12 -> 0 | C13: =+C12 -> 0 | D13: =+D12+0.001 -> 0.001
A14: =+A13 -> 0 | B14: =+B13 -> 0 | C14: =+C13 -> 0 | D14: =+D13+0.001 -> 0.002
... A22: =+A21 -> 0 | B22: =+B21 -> 0 | C22: =+C21 -> 0 | D22: =+D21+0.001 -> 0.01
A23: =+A22 -> 0 | B23: =+B22 -> 0 | C23: =+C22 -> 0 | D23: =+D2 -> -0.01
A24: =+A23 -> 0 | B24: =+B23 -> 0 | C24: =+C23 -> 0 | D24: =+D3 -> -0.009
A25: =+A24 -> 0 | B25: =+B24 -> 0 | C25: =+C24 -> 0 | D25: =+D4 -> -0.008
A26: =+A25 -> 0 | B26: =+B25 -> 0 | C26: =+C25 -> 0 | D26: =+D5 -> -0.007
A27: =+A26 -> 0 | B27: =+B26 -> 0 | C27: =+C26 -> 0 | D27: =+D6 -> -0.006
A28: =+A27 -> 0 | B28: =+B27 -> 0 | C28: =+C27 -> 0 | D28: =+D7 -> -0.005
A29: =+A28 -> 0 | B29: =+B28 -> 0 | C29: =+C28 -> 0 | D29: =+D8 -> -0.004
A30: =+A29 -> 0 | B30: =+B29 -> 0 | C30: =+C29 -> 0 | D30: =+D9 -> -0.003
A31: =+A30 -> 0 | B31: =+B30 -> 0 | C31: =+C30 -> 0 | D31: =+D10 -> -0.002
A32: =+A31 -> 0 | B32: =+B31 -> 0 | C32: =+C31 -> 0 | D32: =+D11 -> -0.001
A33: =+A32 -> 0 | B33: =+B32 -> 0 | C33: =+C32 -> 0 | D33: =+D12 -> 0
A34: =+A33 -> 0 | B34: =+B33 -> 0 | C34: =+C33 -> 0 | D34: =+D13 -> 0.001
... A211: =+A210 -> 0 | B211: =+B210 -> 0 | C211: =+C210 -> 0 | D211: =+D190 -> 0.01

Sheet Beam.Y
A1: Gaussian waist, mm⁻¹ | B1: Beam aperture, mm⁻¹ | C1: Incidence angle, mrad | D1: Wavefront curvature, mm⁻¹ | E1: Aberration function
A2: 0 | B2: 0 | C2: 0 | D2: -0.01
A3: =+A2 -> 0 | B3: =+B2 -> 0 | C3: =+C2 -> 0 | D3: =+D2+0.001 -> -0.009
A4: =+A3 -> 0 | B4: =+B3 -> 0 | C4: =+C3 -> 0 | D4: =+D3+0.001 -> -0.008
A5: =+A4 -> 0 | B5: =+B4 -> 0 | C5: =+C4 -> 0 | D5: =+D4+0.001 -> -0.007
A6: =+A5 -> 0 | B6: =+B5 -> 0 | C6: =+C5 -> 0 | D6: =+D5+0.001 -> -0.006
A7: =+A6 -> 0 | B7: =+B6 -> 0 | C7: =+C6 -> 0 | D7: =+D6+0.001 -> -0.005
A8: =+A7 -> 0 | B8: =+B7 -> 0 | C8: =+C7 -> 0 | D8: =+D7+0.001 -> -0.004
A9: =+A8 -> 0 | B9: =+B8 -> 0 | C9: =+C8 -> 0 | D9: =+D8+0.001 -> -0.003
A10: =+A9 -> 0 | B10: =+B9 -> 0 | C10: =+C9 -> 0 | D10: =+D9+0.001 -> -0.002
A11: =+A10 -> 0 | B11: =+B10 -> 0 | C11: =+C10 -> 0 | D11: =+D10+0.001 -> -0.001
A12: =+A11 -> 0 | B12: =+B11 -> 0 | C12: =+C11 -> 0 | D12: =+D11+0.001 -> 0
A13: =+A12 -> 0 | B13: =+B12 -> 0 | C13: =+C12 -> 0 | D13: =+D12+0.001 -> 0.001
A14: =+A13 -> 0 | B14: =+B13 -> 0 | C14: =+C13 -> 0 | D14: =+D13+0.001 -> 0.002
... A22: =+A21 -> 0 | B22: =+B21 -> 0 | C22: =+C21 -> 0 | D22: =+D21+0.001 -> 0.01
A23: =+A22 -> 0 | B23: =+B22 -> 0 | C23: =+C22 -> 0 | D23: =+D2 -> -0.01
A24: =+A23 -> 0 | B24: =+B23 -> 0 | C24: =+C23 -> 0 | D24: =+D3 -> -0.009
A25: =+A24 -> 0 | B25: =+B24 -> 0 | C25: =+C24 -> 0 | D25: =+D4 -> -0.008
A26: =+A25 -> 0 | B26: =+B25 -> 0 | C26: =+C25 -> 0 | D26: =+D5 -> -0.007
A27: =+A26 -> 0 | B27: =+B26 -> 0 | C27: =+C26 -> 0 | D27: =+D6 -> -0.006
A28: =+A27 -> 0 | B28: =+B27 -> 0 | C28: =+C27 -> 0 | D28: =+D7 -> -0.005
A29: =+A28 -> 0 | B29: =+B28 -> 0 | C29: =+C28 -> 0 | D29: =+D8 -> -0.004
A30: =+A29 -> 0 | B30: =+B29 -> 0 | C30: =+C29 -> 0 | D30: =+D9 -> -0.003
A31: =+A30 -> 0 | B31: =+B30 -> 0 | C31: =+C30 -> 0 | D31: =+D10 -> -0.002
A32: =+A31 -> 0 | B32: =+B31 -> 0 | C32: =+C31 -> 0 | D32: =+D11 -> -0.001
A33: =+A32 -> 0 | B33: =+B32 -> 0 | C33: =+C32 -> 0 | D33: =+D12 -> 0
A34: =+A33 -> 0 | B34: =+B33 -> 0 | C34: =+C33 -> 0 | D34: =+D13 -> 0.001
... A106: =+A105 -> 0 | B106: =+B105 -> 0 | C106: =+C105 -> 0 | D106: =+D85 -> 0.01
A107: =+A106 -> 0 | B107: =+B106 -> 0 | C107: =+C106 -> 0 | D107: =-Beam.X!D107 -> 0.01
A108: =+A107 -> 0 | B108: =+B107 -> 0 | C108: =+C107 -> 0 | D108: =-Beam.X!D108 -> 0.009
A109: =+A108 -> 0 | B109: =+B108 -> 0 | C109: =+C108 -> 0 | D109: =-Beam.X!D109 -> 0.008
A110: =+A109 -> 0 | B110: =+B109 -> 0 | C110: =+C109 -> 0 | D110: =-Beam.X!D110 -> 0.007
A111: =+A110 -> 0 | B111: =+B110 -> 0 | C111: =+C110 -> 0 | D111: =-Beam.X!D111 -> 0.006
A112: =+A111 -> 0 | B112: =+B111 -> 0 | C112: =+C111 -> 0 | D112: =-Beam.X!D112 -> 0.005
A113: =+A112 -> 0 | B113: =+B112 -> 0 | C113: =+C112 -> 0 | D113: =-Beam.X!D113 -> 0.004
A114: =+A113 -> 0 | B114: =+B113 -> 0 | C114: =+C113 -> 0 | D114: =-Beam.X!D114 -> 0.003
A115: =+A114 -> 0 | B115: =+B114 -> 0 | C115: =+C114 -> 0 | D115: =-Beam.X!D115 -> 0.002
A116: =+A115 -> 0 | B116: =+B115 -> 0 | C116: =+C115 -> 0 | D116: =-Beam.X!D116 -> 0.001
A117: =+A116 -> 0 | B117: =+B116 -> 0 | C117: =+C116 -> 0 | D117: =-Beam.X!D117 -> 0
A118: =+A117 -> 0 | B118: =+B117 -> 0 | C118: =+C117 -> 0 | D118: =-Beam.X!D118 -> -0.001
...

Sheet Psd
A1: Distance, mm | B1: Image aperture, mm | C1: Lateral step, μm | D1: Step division
A2: 40 | B2: 2 | C2: 5 | D2: 40
A3: =+A2 -> 40 | B3: =+B2 -> 2 | C3: =+C2 -> 5 | D3: =+D2 -> 40
A4: =+A3 -> 40 | B4: =+B3 -> 2 | C4: =+C3 -> 5 | D4: =+D3 -> 40
A5: =+A4 -> 40 | B5: =+B4 -> 2 | C5: =+C4 -> 5 | D5: =+D4 -> 40
A6: =+A5 -> 40 | B6: =+B5 -> 2 | C6: =+C5 -> 5 | D6: =+D5 -> 40
A7: =+A6 -> 40 | B7: =+B6 -> 2 | C7: =+C6 -> 5 | D7: =+D6 -> 40
A8: =+A7 -> 40 | B8: =+B7 -> 2 | C8: =+C7 -> 5 | D8: =+D7 -> 40
A9: =+A8 -> 40 | B9: =+B8 -> 2 | C9: =+C8 -> 5 | D9: =+D8 -> 40
A10: =+A9 -> 40 | B10: =+B9 -> 2 | C10: =+C9 -> 5 | D10: =+D9 -> 40
A11: =+A10 -> 40 | B11: =+B10 -> 2 | C11: =+C10 -> 5 | D11: =+D10 -> 40
A12: =+A11 -> 40 | B12: =+B11 -> 2 | C12: =+C11 -> 5 | D12: =+D11 -> 40
A13: =+A12 -> 40 | B13: =+B12 -> 2 | C13: =+C12 -> 5 | D13: =+D12 -> 40
A14: =+A13 -> 40 | B14: =+B13 -> 2 | C14: =+C13 -> 5 | D14: =+D13 -> 40
... A211: =+A210 -> 40 | B211: =+B210 -> 2 | C211: =+C210 -> 5 | D211: =+D210 -> 40

Sheet Add
A1: Accuracy, % | B1: Debug data | C1: Save data
A2: 1 | B2: Y | C2: Y
A3: =+A2 -> 1 | B3: =+B2 -> Y | C3: =+C2 -> Y
A4: =+A3 -> 1 | B4: =+B3 -> Y | C4: =+C3 -> Y
A5: =+A4 -> 1 | B5: =+B4 -> Y | C5: =+C4 -> Y
A6: =+A5 -> 1 | B6: =+B5 -> Y | C6: =+C5 -> Y
A7: =+A6 -> 1 | B7: =+B6 -> Y | C7: =+C6 -> Y
A8: =+A7 -> 1 | B8: =+B7 -> Y | C8: =+C7 -> Y
A9: =+A8 -> 1 | B9: =+B8 -> Y | C9: =+C8 -> Y
A10: =+A9 -> 1 | B10: =+B9 -> Y | C10: =+C9 -> Y
A11: =+A10 -> 1 | B11: =+B10 -> Y | C11: =+C10 -> Y
A12: =+A11 -> 1 | B12: =+B11 -> Y | C12: =+C11 -> Y
A13: =+A12 -> 1 | B13: =+B12 -> Y | C13: =+C12 -> Y
A14: =+A13 -> 1 | B14: =+B13 -> Y | C14: =+C13 -> Y
... A211: =+A210 -> 1 | B211: =+B210 -> Y | C211: =+C210 -> Y

Sheet Dependencies
A1: List of dependencies
