Workbook

Sheet Grating
A1: Slit form and type | B1: Period, μm | C1: Duty factor | D1: Slit depth, mm | E1: Refractive index
A2: 1D,square, | B2: 100 | C2: 0.5 | D2: =0.6*0.0007 -> 0.00042 | E2: 1.4738 | F2: -25.593
A3: =+A2 -> 1D,square, | B3: =+B2 -> 100 | C3: =+C2 -> 0.5 | D3: =+D2 -> 0.00042 | E3: =+E2 -> 1.4738 | F3: =+F2 -> -25.593
A4: =+A3 -> 1D,square, | B4: =+B3 -> 100 | C4: =+C3 -> 0.5 | D4: =+D3 -> 0.00042 | E4: =+E3 -> 1.4738 | F4: =+F3 -> -25.593
A5: =+A4 -> 1D,square, | B5: =+B4 -> 100 | C5: =+C4 -> 0.5 | D5: =+D4 -> 0.00042 | E5: =+E4 -> 1.4738 | F5: =+F4 -> -25.593
A6: =+A5 -> 1D,square, | B6: =+B5 -> 100 | C6: =+C5 -> 0.5 | D6: =+D5 -> 0.00042 | E6: =+E5 -> 1.4738 | F6: =+F5 -> -25.593
A7: =+A6 -> 1D,square, | B7: =+B6 -> 100 | C7: =+C6 -> 0.5 | D7: =+D6 -> 0.00042 | E7: =+E6 -> 1.4738 | F7: =+F6 -> -25.593
A8: =+A7 -> 1D,square, | B8: =+B7 -> 100 | C8: =+C7 -> 0.5 | D8: =+D7 -> 0.00042 | E8: =+E7 -> 1.4738 | F8: =+F7 -> -25.593
A9: =+A8 -> 1D,square, | B9: =+B8 -> 100 | C9: =+C8 -> 0.5 | D9: =+D8 -> 0.00042 | E9: =+E8 -> 1.4738 | F9: =+F8 -> -25.593
A10: =+A9 -> 1D,square, | B10: =+B9 -> 100 | C10: =+C9 -> 0.5 | D10: =+D9 -> 0.00042 | E10: =+E9 -> 1.4738 | F10: =+F9 -> -25.593
A11: =+A10 -> 1D,square, | B11: =+B10 -> 100 | C11: =+C10 -> 0.5 | D11: =+D10 -> 0.00042 | E11: =+E10 -> 1.4738 | F11: =+F10 -> -25.593
A12: =+A11 -> 1D,square, | B12: =+B11 -> 100 | C12: =+C11 -> 0.5 | D12: =+D11 -> 0.00042 | E12: =+E11 -> 1.4738 | F12: =+F11 -> -25.593
A13: =+A12 -> 1D,square, | B13: =+B12 -> 100 | C13: =+C12 -> 0.5 | D13: =+D12 -> 0.00042 | E13: =+E12 -> 1.4738 | F13: =+F12 -> -25.593
A14: =+A13 -> 1D,square, | B14: =+B13 -> 100 | C14: =+C13 -> 0.5 | D14: =+D13 -> 0.00042 | E14: =+E13 -> 1.4738 | F14: =+F13 -> -25.593
... A1602: =+A1601 -> 1D,square, | B1602: =+B1601 -> 100 | C1602: =+C1601 -> 0.5 | D1602: =+D1601 -> 0.00042 | E1602: =+E1601 -> 1.4738 | F1602: =+F1601 -> -25.593

Sheet Dispersion
A1: Wavelength | C1: n^2 | D1: n
A2: 486 | B2: =+A2*0.001 -> 0.486 | C2: =1+0.6961663*B2*B2/(B2*B2-0.0684043*0.0684043)+0.4079426*B2*B2/(B2*B2-0.1162414*0.1162414)+0.8974794*B2*B2/(B2*B2-9.896161*9.896161) -> 2.1407625 | D2: =+SQRT(C2) -> 1.4631345 | E2: =+A2*0.000001 -> 0.000486
A3: =+A2+2 -> 488 | B3: =+A3*0.001 -> 0.488 | C3: =1+0.6961663*B3*B3/(B3*B3-0.0684043*0.0684043)+0.4079426*B3*B3/(B3*B3-0.1162414*0.1162414)+0.8974794*B3*B3/(B3*B3-9.896161*9.896161) -> 2.1404125 | D3: =+SQRT(C3) -> 1.4630149 | E3: =+A3*0.000001 -> 0.000488
A4: =+A3+2 -> 490 | B4: =+A4*0.001 -> 0.49 | C4: =1+0.6961663*B4*B4/(B4*B4-0.0684043*0.0684043)+0.4079426*B4*B4/(B4*B4-0.1162414*0.1162414)+0.8974794*B4*B4/(B4*B4-9.896161*9.896161) -> 2.1400667 | D4: =+SQRT(C4) -> 1.4628967 | E4: =+A4*0.000001 -> 0.00049
A5: =+A4+2 -> 492 | B5: =+A5*0.001 -> 0.492 | C5: =1+0.6961663*B5*B5/(B5*B5-0.0684043*0.0684043)+0.4079426*B5*B5/(B5*B5-0.1162414*0.1162414)+0.8974794*B5*B5/(B5*B5-9.896161*9.896161) -> 2.1397251 | D5: =+SQRT(C5) -> 1.4627799 | E5: =+A5*0.000001 -> 0.000492
A6: =+A5+2 -> 494 | B6: =+A6*0.001 -> 0.494 | C6: =1+0.6961663*B6*B6/(B6*B6-0.0684043*0.0684043)+0.4079426*B6*B6/(B6*B6-0.1162414*0.1162414)+0.8974794*B6*B6/(B6*B6-9.896161*9.896161) -> 2.1393876 | D6: =+SQRT(C6) -> 1.4626645 | E6: =+A6*0.000001 -> 0.000494
A7: =+A6+2 -> 496 | B7: =+A7*0.001 -> 0.496 | C7: =1+0.6961663*B7*B7/(B7*B7-0.0684043*0.0684043)+0.4079426*B7*B7/(B7*B7-0.1162414*0.1162414)+0.8974794*B7*B7/(B7*B7-9.896161*9.896161) -> 2.139054 | D7: =+SQRT(C7) -> 1.4625505 | E7: =+A7*0.000001 -> 0.000496
A8: =+A7+2 -> 498 | B8: =+A8*0.001 -> 0.498 | C8: =1+0.6961663*B8*B8/(B8*B8-0.0684043*0.0684043)+0.4079426*B8*B8/(B8*B8-0.1162414*0.1162414)+0.8974794*B8*B8/(B8*B8-9.896161*9.896161) -> 2.1387245 | D8: =+SQRT(C8) -> 1.4624378 | E8: =+A8*0.000001 -> 0.000498
A9: =+A8+2 -> 500 | B9: =+A9*0.001 -> 0.5 | C9: =1+0.6961663*B9*B9/(B9*B9-0.0684043*0.0684043)+0.4079426*B9*B9/(B9*B9-0.1162414*0.1162414)+0.8974794*B9*B9/(B9*B9-9.896161*9.896161) -> 2.1383988 | D9: =+SQRT(C9) -> 1.4623265 | E9: =+A9*0.000001 -> 0.0005
A10: =+A9+2 -> 502 | B10: =+A10*0.001 -> 0.502 | C10: =1+0.6961663*B10*B10/(B10*B10-0.0684043*0.0684043)+0.4079426*B10*B10/(B10*B10-0.1162414*0.1162414)+0.8974794*B10*B10/(B10*B10-9.896161*9.896161) -> 2.1380768 | D10: =+SQRT(C10) -> 1.4622164 | E10: =+A10*0.000001 -> 0.000502
A11: =+A10+2 -> 504 | B11: =+A11*0.001 -> 0.504 | C11: =1+0.6961663*B11*B11/(B11*B11-0.0684043*0.0684043)+0.4079426*B11*B11/(B11*B11-0.1162414*0.1162414)+0.8974794*B11*B11/(B11*B11-9.896161*9.896161) -> 2.1377587 | D11: =+SQRT(C11) -> 1.4621076 | E11: =+A11*0.000001 -> 0.000504
A12: =+A11+2 -> 506 | B12: =+A12*0.001 -> 0.506 | C12: =1+0.6961663*B12*B12/(B12*B12-0.0684043*0.0684043)+0.4079426*B12*B12/(B12*B12-0.1162414*0.1162414)+0.8974794*B12*B12/(B12*B12-9.896161*9.896161) -> 2.1374442 | D12: =+SQRT(C12) -> 1.4620001 | E12: =+A12*0.000001 -> 0.000506
A13: =+A12+2 -> 508 | B13: =+A13*0.001 -> 0.508 | C13: =1+0.6961663*B13*B13/(B13*B13-0.0684043*0.0684043)+0.4079426*B13*B13/(B13*B13-0.1162414*0.1162414)+0.8974794*B13*B13/(B13*B13-9.896161*9.896161) -> 2.1371333 | D13: =+SQRT(C13) -> 1.4618937 | E13: =+A13*0.000001 -> 0.000508
A14: =+A13+2 -> 510 | B14: =+A14*0.001 -> 0.51 | C14: =1+0.6961663*B14*B14/(B14*B14-0.0684043*0.0684043)+0.4079426*B14*B14/(B14*B14-0.1162414*0.1162414)+0.8974794*B14*B14/(B14*B14-9.896161*9.896161) -> 2.136826 | D14: =+SQRT(C14) -> 1.4617886 | E14: =+A14*0.000001 -> 0.00051
... A211: =+A210+2 -> 904 | B211: =+A211*0.001 -> 0.904 | C211: =1+0.6961663*B211*B211/(B211*B211-0.0684043*0.0684043)+0.4079426*B211*B211/(B211*B211-0.1162414*0.1162414)+0.8974794*B211*B211/(B211*B211-9.896161*9.896161) -> 2.1074242 | D211: =+SQRT(C211) -> 1.451697 | E211: =+A211*0.000001 -> 0.000904

Sheet Beam
A1: Wavelength, nm | B1: Band width, % | C1: Intensity, W/mm²
A2: 500 | B2: 10 | C2: 1
A3: =+A2 -> 500 | B3: =+B2 -> 10 | C3: =+C2 -> 1
A4: =+A3 -> 500 | B4: =+B3 -> 10 | C4: =+C3 -> 1
A5: =+A4 -> 500 | B5: =+B4 -> 10 | C5: =+C4 -> 1
A6: =+A5 -> 500 | B6: =+B5 -> 10 | C6: =+C5 -> 1
A7: =+A6 -> 500 | B7: =+B6 -> 10 | C7: =+C6 -> 1
A8: =+A7 -> 500 | B8: =+B7 -> 10 | C8: =+C7 -> 1
A9: =+A8 -> 500 | B9: =+B8 -> 10 | C9: =+C8 -> 1
A10: =+A9 -> 500 | B10: =+B9 -> 10 | C10: =+C9 -> 1
A11: =+A10 -> 500 | B11: =+B10 -> 10 | C11: =+C10 -> 1
A12: =+A11 -> 500 | B12: =+B11 -> 10 | C12: =+C11 -> 1
A13: =+A12 -> 500 | B13: =+B12 -> 10 | C13: =+C12 -> 1
A14: =+A13 -> 500 | B14: =+B13 -> 10 | C14: =+C13 -> 1
... A1602: =+A1601 -> 500 | B1602: =+B1601 -> 10 | C1602: =+C1601 -> 1

Sheet Beam.X
A1: Gaussian waist, mm⁻¹ | B1: Beam aperture, mm⁻¹ | C1: Incidence angle, mrad | D1: Wavefront curvature, mm⁻¹ | E1: Aberration function
A2: 0 | B2: 0 | C2: 0 | D2: =1/(100*2*Grating!B2*Grating!B2/Beam!A2) -> 0.00025
A3: =+A2 -> 0 | B3: =+B2 -> 0 | C3: =+C2 -> 0 | D3: =+D2 -> 0.00025
A4: =+A3 -> 0 | B4: =+B3 -> 0 | C4: =+C3 -> 0 | D4: =+D3 -> 0.00025
A5: =+A4 -> 0 | B5: =+B4 -> 0 | C5: =+C4 -> 0 | D5: =+D4 -> 0.00025
A6: =+A5 -> 0 | B6: =+B5 -> 0 | C6: =+C5 -> 0 | D6: =+D5 -> 0.00025
A7: =+A6 -> 0 | B7: =+B6 -> 0 | C7: =+C6 -> 0 | D7: =+D6 -> 0.00025
A8: =+A7 -> 0 | B8: =+B7 -> 0 | C8: =+C7 -> 0 | D8: =+D7 -> 0.00025
A9: =+A8 -> 0 | B9: =+B8 -> 0 | C9: =+C8 -> 0 | D9: =+D8 -> 0.00025
A10: =+A9 -> 0 | B10: =+B9 -> 0 | C10: =+C9 -> 0 | D10: =+D9 -> 0.00025
A11: =+A10 -> 0 | B11: =+B10 -> 0 | C11: =+C10 -> 0 | D11: =+D10 -> 0.00025
A12: =+A11 -> 0 | B12: =+B11 -> 0 | C12: =+C11 -> 0 | D12: =+D11 -> 0.00025
A13: =+A12 -> 0 | B13: =+B12 -> 0 | C13: =+C12 -> 0 | D13: =+D12 -> 0.00025
A14: =+A13 -> 0 | B14: =+B13 -> 0 | C14: =+C13 -> 0 | D14: =+D13 -> 0.00025
... A1602: =+A1601 -> 0 | B1602: =+B1601 -> 0 | C1602: =+C1601 -> 0 | D1602: =+D1601 -> 0.00025

Sheet Beam.Y
A1: Gaussian waist, mm⁻¹ | B1: Beam aperture, mm⁻¹ | C1: Incidence angle, mrad | D1: Wavefront curvature, mm⁻¹ | E1: Aberration function
A2: 0 | B2: 0 | C2: 0 | D2: 0
A3: =+A2 -> 0 | B3: =+B2 -> 0 | C3: =+C2 -> 0 | D3: =+D2 -> 0
A4: =+A3 -> 0 | B4: =+B3 -> 0 | C4: =+C3 -> 0 | D4: =+D3 -> 0
A5: =+A4 -> 0 | B5: =+B4 -> 0 | C5: =+C4 -> 0 | D5: =+D4 -> 0
A6: =+A5 -> 0 | B6: =+B5 -> 0 | C6: =+C5 -> 0 | D6: =+D5 -> 0
A7: =+A6 -> 0 | B7: =+B6 -> 0 | C7: =+C6 -> 0 | D7: =+D6 -> 0
A8: =+A7 -> 0 | B8: =+B7 -> 0 | C8: =+C7 -> 0 | D8: =+D7 -> 0
A9: =+A8 -> 0 | B9: =+B8 -> 0 | C9: =+C8 -> 0 | D9: =+D8 -> 0
A10: =+A9 -> 0 | B10: =+B9 -> 0 | C10: =+C9 -> 0 | D10: =+D9 -> 0
A11: =+A10 -> 0 | B11: =+B10 -> 0 | C11: =+C10 -> 0 | D11: =+D10 -> 0
A12: =+A11 -> 0 | B12: =+B11 -> 0 | C12: =+C11 -> 0 | D12: =+D11 -> 0
A13: =+A12 -> 0 | B13: =+B12 -> 0 | C13: =+C12 -> 0 | D13: =+D12 -> 0
A14: =+A13 -> 0 | B14: =+B13 -> 0 | C14: =+C13 -> 0 | D14: =+D13 -> 0
... A1602: =+A1601 -> 0 | B1602: =+B1601 -> 0 | C1602: =+C1601 -> 0 | D1602: =+D1601 -> 0

Sheet Psd
A1: Distance, mm | B1: Image aperture, mm | C1: Lateral step, μm | D1: Step division | I1: N | J1: Z_T, mm
A2: =I2*J2*(1+I2*J2*Beam.X!D2) -> 0 | B2: 0.006 | C2: 1 | D2: 1 | I2: 0 | J2: =[1]Grating!B2*[1]Grating!B2*2/[1]Beam!A2 -> 40
A3: =I3*J3*(1+I3*J3*Beam.X!D3) -> 0.5000625 | B3: =+B2 -> 0.006 | C3: =+C2 -> 1 | D3: =+D2 -> 1 | I3: =+I2+20/1600 -> 0.0125 | J3: =[1]Grating!B3*[1]Grating!B3*2/[1]Beam!A3 -> 40
A4: =I4*J4*(1+I4*J4*Beam.X!D4) -> 1.00025 | B4: =+B3 -> 0.006 | C4: =+C3 -> 1 | D4: =+D3 -> 1 | I4: =+I3+20/1600 -> 0.025 | J4: =[1]Grating!B4*[1]Grating!B4*2/[1]Beam!A4 -> 40
A5: =I5*J5*(1+I5*J5*Beam.X!D5) -> 1.5005625 | B5: =+B4 -> 0.006 | C5: =+C4 -> 1 | D5: =+D4 -> 1 | I5: =+I4+20/1600 -> 0.0375 | J5: =[1]Grating!B5*[1]Grating!B5*2/[1]Beam!A5 -> 40
A6: =I6*J6*(1+I6*J6*Beam.X!D6) -> 2.001 | B6: =+B5 -> 0.006 | C6: =+C5 -> 1 | D6: =+D5 -> 1 | I6: =+I5+20/1600 -> 0.05 | J6: =[1]Grating!B6*[1]Grating!B6*2/[1]Beam!A6 -> 40
A7: =I7*J7*(1+I7*J7*Beam.X!D7) -> 2.5015625 | B7: =+B6 -> 0.006 | C7: =+C6 -> 1 | D7: =+D6 -> 1 | I7: =+I6+20/1600 -> 0.0625 | J7: =[1]Grating!B7*[1]Grating!B7*2/[1]Beam!A7 -> 40
A8: =I8*J8*(1+I8*J8*Beam.X!D8) -> 3.00225 | B8: =+B7 -> 0.006 | C8: =+C7 -> 1 | D8: =+D7 -> 1 | I8: =+I7+20/1600 -> 0.075 | J8: =[1]Grating!B8*[1]Grating!B8*2/[1]Beam!A8 -> 40
A9: =I9*J9*(1+I9*J9*Beam.X!D9) -> 3.5030625 | B9: =+B8 -> 0.006 | C9: =+C8 -> 1 | D9: =+D8 -> 1 | I9: =+I8+20/1600 -> 0.0875 | J9: =[1]Grating!B9*[1]Grating!B9*2/[1]Beam!A9 -> 40
A10: =I10*J10*(1+I10*J10*Beam.X!D10) -> 4.004 | B10: =+B9 -> 0.006 | C10: =+C9 -> 1 | D10: =+D9 -> 1 | I10: =+I9+20/1600 -> 0.1 | J10: =[1]Grating!B10*[1]Grating!B10*2/[1]Beam!A10 -> 40
A11: =I11*J11*(1+I11*J11*Beam.X!D11) -> 4.5050625 | B11: =+B10 -> 0.006 | C11: =+C10 -> 1 | D11: =+D10 -> 1 | I11: =+I10+20/1600 -> 0.1125 | J11: =[1]Grating!B11*[1]Grating!B11*2/[1]Beam!A11 -> 40
A12: =I12*J12*(1+I12*J12*Beam.X!D12) -> 5.00625 | B12: =+B11 -> 0.006 | C12: =+C11 -> 1 | D12: =+D11 -> 1 | I12: =+I11+20/1600 -> 0.125 | J12: =[1]Grating!B12*[1]Grating!B12*2/[1]Beam!A12 -> 40
A13: =I13*J13*(1+I13*J13*Beam.X!D13) -> 5.5075625 | B13: =+B12 -> 0.006 | C13: =+C12 -> 1 | D13: =+D12 -> 1 | I13: =+I12+20/1600 -> 0.1375 | J13: =[1]Grating!B13*[1]Grating!B13*2/[1]Beam!A13 -> 40
A14: =I14*J14*(1+I14*J14*Beam.X!D14) -> 6.009 | B14: =+B13 -> 0.006 | C14: =+C13 -> 1 | D14: =+D13 -> 1 | I14: =+I13+20/1600 -> 0.15 | J14: =[1]Grating!B14*[1]Grating!B14*2/[1]Beam!A14 -> 40
... A1602: =I1602*J1602*(1+I1602*J1602*Beam.X!D1602) -> 960 | B1602: =+B1601 -> 0.006 | C1602: =+C1601 -> 1 | D1602: =+D1601 -> 1 | I1602: =+I1601+20/1600 -> 20 | J1602: =[1]Grating!B1602*[1]Grating!B1602*2/[1]Beam!A1602 -> 40

Sheet Add
A1: Accuracy, % | B1: Debug data | C1: Save data
A2: 1 | B2: N | C2: N
A3: =+A2 -> 1 | B3: N | C3: N
A4: =+A3 -> 1 | B4: N | C4: N
A5: =+A4 -> 1 | B5: N | C5: N
A6: =+A5 -> 1 | B6: N | C6: N
A7: =+A6 -> 1 | B7: N | C7: N
A8: =+A7 -> 1 | B8: N | C8: N
A9: =+A8 -> 1 | B9: N | C9: N
A10: =+A9 -> 1 | B10: N | C10: N
A11: =+A10 -> 1 | B11: N | C11: N
A12: =+A11 -> 1 | B12: N | C12: N
A13: =+A12 -> 1 | B13: N | C13: N
A14: =+A13 -> 1 | B14: N | C14: N
... A26: =+A25 -> 1 | B26: N | C26: N
A27: =+A26 -> 1 | B27: N | C27: =+C19 -> N
A28: =+A27 -> 1 | B28: N | C28: =+C20 -> N
A29: =+A28 -> 1 | B29: N | C29: =+C21 -> N
A30: =+A29 -> 1 | B30: N | C30: =+C22 -> N
A31: =+A30 -> 1 | B31: N | C31: =+C23 -> N
A32: =+A31 -> 1 | B32: N | C32: =+C24 -> N
A33: =+A32 -> 1 | B33: N | C33: =+C25 -> N
A34: =+A33 -> 1 | B34: N | C34: =+C26 -> N
A35: =+A34 -> 1 | B35: N | C35: =+C27 -> N
A36: =+A35 -> 1 | B36: N | C36: =+C28 -> N
A37: =+A36 -> 1 | B37: N | C37: =+C29 -> N
A38: =+A37 -> 1 | B38: N | C38: =+C30 -> N
... A99: =+A98 -> 1 | B99: N | C99: =+C91 -> N
A100: =+A99 -> 1 | B100: N | C100: =+C2 -> N
A101: =+A100 -> 1 | B101: N | C101: =+C3 -> N
A102: =+A101 -> 1 | B102: N | C102: =+C4 -> N
A103: =+A102 -> 1 | B103: N | C103: =+C5 -> N
A104: =+A103 -> 1 | B104: N | C104: =+C6 -> N
A105: =+A104 -> 1 | B105: N | C105: =+C7 -> N
A106: =+A105 -> 1 | B106: N | C106: =+C8 -> N
A107: =+A106 -> 1 | B107: N | C107: =+C9 -> N
A108: =+A107 -> 1 | B108: N | C108: =+C10 -> N
A109: =+A108 -> 1 | B109: N | C109: =+C11 -> N
A110: =+A109 -> 1 | B110: N | C110: =+C12 -> N
A111: =+A110 -> 1 | B111: N | C111: =+C13 -> N
...

Sheet Dependencies
A1: List of dependencies
A2: distance
